{"version":1,"ops":[{"type":3,"author":{"id":"3c87de25ab8b2ec3449081ec888ea2a273bb79fc"},"timestamp":1549644365,"metadata":{"github-id":"MDEyOklzc3VlQ29tbWVudDQ2MTg2Njg1Nw==","github-url":"https://github.com/firecat53/keepmenu/issues/27#issuecomment-461866857"},"message":"What do you mean \"typing my password in keepmenu\"? You have a gpg command in your config.ini set to automatically provide the password to open keepmenu. \n\nDo you mean when you select a entry from keepmenu to get typed? Does it do that with all your passwords or just one? Will it type a different field such as the username?","files":null},{"type":3,"author":{"id":"659e07177e84c4ab2c60eb2b276c03458373fbf7"},"timestamp":1549644577,"metadata":{"github-id":"MDEyOklzc3VlQ29tbWVudDQ2MTg2ODEwNw==","github-url":"https://github.com/firecat53/keepmenu/issues/27#issuecomment-461868107"},"message":"Sorry, my report was unclear. Here's what happens:\n1). Launch \"keepmenu\".\n2) Unlock GPG key in pinentry.\n3) Error message appears. No keepass entry gets displayed.","files":null},{"type":3,"author":{"id":"3c87de25ab8b2ec3449081ec888ea2a273bb79fc"},"timestamp":1549644885,"metadata":{"github-id":"MDEyOklzc3VlQ29tbWVudDQ2MTg2OTg3Mw==","github-url":"https://github.com/firecat53/keepmenu/issues/27#issuecomment-461869873"},"message":"Ah, it's probably something to do with the unlock process. I use gpg-agent to keep mine unlocked so that's probably why I haven't seen that issue. I'll play with today and see if I can reproduce (at work...so maybe :) ).","files":null},{"type":3,"author":{"id":"659e07177e84c4ab2c60eb2b276c03458373fbf7"},"timestamp":1549645018,"metadata":{"github-id":"MDEyOklzc3VlQ29tbWVudDQ2MTg3MDY2Ng==","github-url":"https://github.com/firecat53/keepmenu/issues/27#issuecomment-461870666"},"message":"Ok, thanks :) Now that you mention it, it also happens when the key is already unlocked.","files":null},{"type":3,"author":{"id":"3c87de25ab8b2ec3449081ec888ea2a273bb79fc"},"timestamp":1549669305,"metadata":{"github-id":"MDEyOklzc3VlQ29tbWVudDQ2MTg3NjM4OA==","github-url":"https://github.com/firecat53/keepmenu/issues/27#issuecomment-461876388"},"message":"So you can't unlock the database at all using the gpg command? How about if you don't use password_cmd and just type your password directly? And how about actually putting your password into the config file? Just trying to see where it fails.\n\nDo you have any Unicode characters in your password?","files":null},{"type":6,"author":{"id":"3c87de25ab8b2ec3449081ec888ea2a273bb79fc"},"timestamp":1549669305,"metadata":{"github-id":"MDE1OlVzZXJDb250ZW50RWRpdDE4MjE1OTA1OQ=="},"target":"cf5065c32a3a76db3491c10eae62312727fa298282c2e9f72d8d3aba9e664745","message":"So you can't unlock the database at all using the gpg command? How about if you don't use password_cmd and just type your password directly? And how about actually putting your password into the config file? Just trying to see where it fails.\n\nDo you have any Unicode characters in your password?\n\nEdit: I still can't reproduce. I'm using all the same versions as you, tested with gpg command in config.ini including unlocking gpg without the agent running. Please check above for more questions. Also, how did you install keepmenu? Are you running from inside a virtualenv?","files":null},{"type":3,"author":{"id":"659e07177e84c4ab2c60eb2b276c03458373fbf7"},"timestamp":1549669979,"metadata":{"github-id":"MDEyOklzc3VlQ29tbWVudDQ2MTk4NTY1MA==","github-url":"https://github.com/firecat53/keepmenu/issues/27#issuecomment-461985650"},"message":"It works neither when I add the password in the config file, nor when I type it directly in keepmenu. My password does not contain Unicode characters, only letters, numbers and special characters. I tried with a test database with a password containing special characters and spaces in its filename, and it works fine, though.\n\nI installed keepmenu from the AUR, but the same error is displayed when I simply run it from a git repo clone. Not using a virtualenv.","files":null},{"type":6,"author":{"id":"659e07177e84c4ab2c60eb2b276c03458373fbf7"},"timestamp":1549669979,"metadata":{"github-id":"MDE1OlVzZXJDb250ZW50RWRpdDE4MjE2MTM3Mg=="},"target":"eff14e72b6a37dd5985a694948cb5670cac561da0dd4ff25dc8ffb8567f3bd41","message":"It works neither when I add the password in the config file, nor when I type it directly in keepmenu. My password does not contain Unicode characters, only letters, numbers and special characters. I tried with a test database with a password containing special characters and spaces in its filename, and it works fine, though.\n\nI installed keepmenu from the AUR, but the same error is displayed when I simply run it from a git repo clone. Not using a virtualenv.\n\nEdit: Forgot to mention that the db does open without any problems in keepassxc.","files":null},{"type":3,"author":{"id":"659e07177e84c4ab2c60eb2b276c03458373fbf7"},"timestamp":1549670570,"metadata":{"github-id":"MDEyOklzc3VlQ29tbWVudDQ2MTk4ODAyNA==","github-url":"https://github.com/firecat53/keepmenu/issues/27#issuecomment-461988024"},"message":"Here's the error I get when I open the db with keepmenu 0.5.5 (no error is display with 0.5.6 or 0.5.7):\n\n`keepmenu-0.5.5\u003e$ ./keepmenu \nxdotool version 3.20160805.1\nTraceback (most recent call last):\n  File \"./keepmenu\", line 1206, in \u003cmodule\u003e\n    MANAGER = client()\n  File \"./keepmenu\", line 1032, in client\n    mgr.connect()\n  File \"/usr/lib/python3.7/multiprocessing/managers.py\", line 512, in connect\n    conn = Client(self._address, authkey=self._authkey)\n  File \"/usr/lib/python3.7/multiprocessing/connection.py\", line 492, in Client\n    c = SocketClient(address)\n  File \"/usr/lib/python3.7/multiprocessing/connection.py\", line 619, in SocketClient\n    s.connect(address)\nConnectionRefusedError: [Errno 111] Connection refused\n\nDuring handling of the above exception, another exception occurred:\n\nTraceback (most recent call last):\n  File \"./keepmenu\", line 1210, in \u003cmodule\u003e\n    run()\n  File \"./keepmenu\", line 1195, in run\n    dmenu = DmenuRunner(server)\n  File \"./keepmenu\", line 1046, in __init__\n    self.kpo = get_entries(self.database)\n  File \"./keepmenu\", line 317, in get_entries\n    kpo = PyKeePass(dbf, password, keyfile=keyfile)\n  File \"/usr/lib/python3.7/site-packages/pykeepass/pykeepass.py\", line 28, in __init__\n    self.read(password=password, keyfile=keyfile)\n  File \"/usr/lib/python3.7/site-packages/pykeepass/pykeepass.py\", line 45, in read\n    keyfile=keyfile\n  File \"/usr/lib/python3.7/site-packages/construct/core.py\", line 325, in parse_file\n    return self.parse_stream(f, **contextkw)\n  File \"/usr/lib/python3.7/site-packages/construct/core.py\", line 316, in parse_stream\n    return self._parsereport(stream, context, \"(parsing)\")\n  File \"/usr/lib/python3.7/site-packages/construct/core.py\", line 328, in _parsereport\n    obj = self._parse(stream, context, path)\n  File \"/usr/lib/python3.7/site-packages/construct/core.py\", line 1979, in _parse\n    subobj = sc._parsereport(stream, context, path)\n  File \"/usr/lib/python3.7/site-packages/construct/core.py\", line 328, in _parsereport\n    obj = self._parse(stream, context, path)\n  File \"/usr/lib/python3.7/site-packages/construct/core.py\", line 2468, in _parse\n    return self.subcon._parsereport(stream, context, path)\n  File \"/usr/lib/python3.7/site-packages/construct/core.py\", line 328, in _parsereport\n    obj = self._parse(stream, context, path)\n  File \"/usr/lib/python3.7/site-packages/construct/core.py\", line 3663, in _parse\n    return sc._parsereport(stream, context, path)\n  File \"/usr/lib/python3.7/site-packages/construct/core.py\", line 328, in _parsereport\n    obj = self._parse(stream, context, path)\n  File \"/usr/lib/python3.7/site-packages/construct/core.py\", line 1979, in _parse\n    subobj = sc._parsereport(stream, context, path)\n  File \"/usr/lib/python3.7/site-packages/construct/core.py\", line 328, in _parsereport\n    obj = self._parse(stream, context, path)\n  File \"/usr/lib/python3.7/site-packages/construct/core.py\", line 2468, in _parse\n    return self.subcon._parsereport(stream, context, path)\n  File \"/usr/lib/python3.7/site-packages/construct/core.py\", line 328, in _parsereport\n    obj = self._parse(stream, context, path)\n  File \"/usr/lib/python3.7/site-packages/construct/core.py\", line 2604, in _parse\n    return self.func(context) if callable(self.func) else self.func\n  File \"/usr/lib/python3.7/site-packages/pykeepass/kdbx_parsing/kdbx4.py\", line 55, in compute_transformed\n    key_composite\n  File \"/usr/lib/python3.7/site-packages/pykeepass/kdbx_parsing/common.py\", line 69, in aes_kdf\n    keyfile=keyfile\n  File \"/usr/lib/python3.7/site-packages/pykeepass/kdbx_parsing/common.py\", line 86, in compute_key_composite\n    password_composite = hashlib.sha256(password.encode('utf-8')).digest()\nAttributeError: 'bytes' object has no attribute 'encode'\n`","files":null},{"type":6,"author":{"id":"659e07177e84c4ab2c60eb2b276c03458373fbf7"},"timestamp":1549670570,"metadata":{"github-id":"MDE1OlVzZXJDb250ZW50RWRpdDE4MjE2MzI3Ng=="},"target":"2fcbe6dfea742e635fd271d5a389a43b56b00c61fb3c92b990ab0a172b2b6f9a","message":"Here's the error I get when I open the db with keepmenu 0.5.5 (no error is display with 0.5.6 or 0.5.7):\n\n`\nkeepmenu-0.5.5\u003e$ ./keepmenu \nxdotool version 3.20160805.1\nTraceback (most recent call last):\n  File \"./keepmenu\", line 1206, in \u003cmodule\u003e\n    MANAGER = client()\n  File \"./keepmenu\", line 1032, in client\n    mgr.connect()\n  File \"/usr/lib/python3.7/multiprocessing/managers.py\", line 512, in connect\n    conn = Client(self._address, authkey=self._authkey)\n  File \"/usr/lib/python3.7/multiprocessing/connection.py\", line 492, in Client\n    c = SocketClient(address)\n  File \"/usr/lib/python3.7/multiprocessing/connection.py\", line 619, in SocketClient\n    s.connect(address)\nConnectionRefusedError: [Errno 111] Connection refused\n\nDuring handling of the above exception, another exception occurred:\n\nTraceback (most recent call last):\n  File \"./keepmenu\", line 1210, in \u003cmodule\u003e\n    run()\n  File \"./keepmenu\", line 1195, in run\n    dmenu = DmenuRunner(server)\n  File \"./keepmenu\", line 1046, in __init__\n    self.kpo = get_entries(self.database)\n  File \"./keepmenu\", line 317, in get_entries\n    kpo = PyKeePass(dbf, password, keyfile=keyfile)\n  File \"/usr/lib/python3.7/site-packages/pykeepass/pykeepass.py\", line 28, in __init__\n    self.read(password=password, keyfile=keyfile)\n  File \"/usr/lib/python3.7/site-packages/pykeepass/pykeepass.py\", line 45, in read\n    keyfile=keyfile\n  File \"/usr/lib/python3.7/site-packages/construct/core.py\", line 325, in parse_file\n    return self.parse_stream(f, **contextkw)\n  File \"/usr/lib/python3.7/site-packages/construct/core.py\", line 316, in parse_stream\n    return self._parsereport(stream, context, \"(parsing)\")\n  File \"/usr/lib/python3.7/site-packages/construct/core.py\", line 328, in _parsereport\n    obj = self._parse(stream, context, path)\n  File \"/usr/lib/python3.7/site-packages/construct/core.py\", line 1979, in _parse\n    subobj = sc._parsereport(stream, context, path)\n  File \"/usr/lib/python3.7/site-packages/construct/core.py\", line 328, in _parsereport\n    obj = self._parse(stream, context, path)\n  File \"/usr/lib/python3.7/site-packages/construct/core.py\", line 2468, in _parse\n    return self.subcon._parsereport(stream, context, path)\n  File \"/usr/lib/python3.7/site-packages/construct/core.py\", line 328, in _parsereport\n    obj = self._parse(stream, context, path)\n  File \"/usr/lib/python3.7/site-packages/construct/core.py\", line 3663, in _parse\n    return sc._parsereport(stream, context, path)\n  File \"/usr/lib/python3.7/site-packages/construct/core.py\", line 328, in _parsereport\n    obj = self._parse(stream, context, path)\n  File \"/usr/lib/python3.7/site-packages/construct/core.py\", line 1979, in _parse\n    subobj = sc._parsereport(stream, context, path)\n  File \"/usr/lib/python3.7/site-packages/construct/core.py\", line 328, in _parsereport\n    obj = self._parse(stream, context, path)\n  File \"/usr/lib/python3.7/site-packages/construct/core.py\", line 2468, in _parse\n    return self.subcon._parsereport(stream, context, path)\n  File \"/usr/lib/python3.7/site-packages/construct/core.py\", line 328, in _parsereport\n    obj = self._parse(stream, context, path)\n  File \"/usr/lib/python3.7/site-packages/construct/core.py\", line 2604, in _parse\n    return self.func(context) if callable(self.func) else self.func\n  File \"/usr/lib/python3.7/site-packages/pykeepass/kdbx_parsing/kdbx4.py\", line 55, in compute_transformed\n    key_composite\n  File \"/usr/lib/python3.7/site-packages/pykeepass/kdbx_parsing/common.py\", line 69, in aes_kdf\n    keyfile=keyfile\n  File \"/usr/lib/python3.7/site-packages/pykeepass/kdbx_parsing/common.py\", line 86, in compute_key_composite\n    password_composite = hashlib.sha256(password.encode('utf-8')).digest()\nAttributeError: 'bytes' object has no attribute 'encode'\n`","files":null},{"type":6,"author":{"id":"659e07177e84c4ab2c60eb2b276c03458373fbf7"},"timestamp":1549670607,"metadata":{"github-id":"MDE1OlVzZXJDb250ZW50RWRpdDE4MjE2MzQxMQ=="},"target":"2fcbe6dfea742e635fd271d5a389a43b56b00c61fb3c92b990ab0a172b2b6f9a","message":"Here's the error I get when I open the db with keepmenu 0.5.5 (no error is display with 0.5.6 or 0.5.7):\n\n`keepmenu-0.5.5\u003e$ ./keepmenu \nxdotool version 3.20160805.1\nTraceback (most recent call last):\n  File \"./keepmenu\", line 1206, in \u003cmodule\u003e\n    MANAGER = client()\n  File \"./keepmenu\", line 1032, in client\n    mgr.connect()\n  File \"/usr/lib/python3.7/multiprocessing/managers.py\", line 512, in connect\n    conn = Client(self._address, authkey=self._authkey)\n  File \"/usr/lib/python3.7/multiprocessing/connection.py\", line 492, in Client\n    c = SocketClient(address)\n  File \"/usr/lib/python3.7/multiprocessing/connection.py\", line 619, in SocketClient\n    s.connect(address)\nConnectionRefusedError: [Errno 111] Connection refused\n\nDuring handling of the above exception, another exception occurred:\n\nTraceback (most recent call last):\n  File \"./keepmenu\", line 1210, in \u003cmodule\u003e\n    run()\n  File \"./keepmenu\", line 1195, in run\n    dmenu = DmenuRunner(server)\n  File \"./keepmenu\", line 1046, in __init__\n    self.kpo = get_entries(self.database)\n  File \"./keepmenu\", line 317, in get_entries\n    kpo = PyKeePass(dbf, password, keyfile=keyfile)\n  File \"/usr/lib/python3.7/site-packages/pykeepass/pykeepass.py\", line 28, in __init__\n    self.read(password=password, keyfile=keyfile)\n  File \"/usr/lib/python3.7/site-packages/pykeepass/pykeepass.py\", line 45, in read\n    keyfile=keyfile\n  File \"/usr/lib/python3.7/site-packages/construct/core.py\", line 325, in parse_file\n    return self.parse_stream(f, **contextkw)\n  File \"/usr/lib/python3.7/site-packages/construct/core.py\", line 316, in parse_stream\n    return self._parsereport(stream, context, \"(parsing)\")\n  File \"/usr/lib/python3.7/site-packages/construct/core.py\", line 328, in _parsereport\n    obj = self._parse(stream, context, path)\n  File \"/usr/lib/python3.7/site-packages/construct/core.py\", line 1979, in _parse\n    subobj = sc._parsereport(stream, context, path)\n  File \"/usr/lib/python3.7/site-packages/construct/core.py\", line 328, in _parsereport\n    obj = self._parse(stream, context, path)\n  File \"/usr/lib/python3.7/site-packages/construct/core.py\", line 2468, in _parse\n    return self.subcon._parsereport(stream, context, path)\n  File \"/usr/lib/python3.7/site-packages/construct/core.py\", line 328, in _parsereport\n    obj = self._parse(stream, context, path)\n  File \"/usr/lib/python3.7/site-packages/construct/core.py\", line 3663, in _parse\n    return sc._parsereport(stream, context, path)\n  File \"/usr/lib/python3.7/site-packages/construct/core.py\", line 328, in _parsereport\n    obj = self._parse(stream, context, path)\n  File \"/usr/lib/python3.7/site-packages/construct/core.py\", line 1979, in _parse\n    subobj = sc._parsereport(stream, context, path)\n  File \"/usr/lib/python3.7/site-packages/construct/core.py\", line 328, in _parsereport\n    obj = self._parse(stream, context, path)\n  File \"/usr/lib/python3.7/site-packages/construct/core.py\", line 2468, in _parse\n    return self.subcon._parsereport(stream, context, path)\n  File \"/usr/lib/python3.7/site-packages/construct/core.py\", line 328, in _parsereport\n    obj = self._parse(stream, context, path)\n  File \"/usr/lib/python3.7/site-packages/construct/core.py\", line 2604, in _parse\n    return self.func(context) if callable(self.func) else self.func\n  File \"/usr/lib/python3.7/site-packages/pykeepass/kdbx_parsing/kdbx4.py\", line 55, in compute_transformed\n    key_composite\n  File \"/usr/lib/python3.7/site-packages/pykeepass/kdbx_parsing/common.py\", line 69, in aes_kdf\n    keyfile=keyfile\n  File \"/usr/lib/python3.7/site-packages/pykeepass/kdbx_parsing/common.py\", line 86, in compute_key_composite\n    password_composite = hashlib.sha256(password.encode('utf-8')).digest()\nAttributeError: 'bytes' object has no attribute 'encode'`","files":null},{"type":6,"author":{"id":"659e07177e84c4ab2c60eb2b276c03458373fbf7"},"timestamp":1549670638,"metadata":{"github-id":"MDE1OlVzZXJDb250ZW50RWRpdDE4MjE2MzUzNg=="},"target":"2fcbe6dfea742e635fd271d5a389a43b56b00c61fb3c92b990ab0a172b2b6f9a","message":"Here's the error I get when I open the db with keepmenu 0.5.5 (no error is displayed with 0.5.6 or 0.5.7):\n\n`keepmenu-0.5.5\u003e$ ./keepmenu \nxdotool version 3.20160805.1\nTraceback (most recent call last):\n  File \"./keepmenu\", line 1206, in \u003cmodule\u003e\n    MANAGER = client()\n  File \"./keepmenu\", line 1032, in client\n    mgr.connect()\n  File \"/usr/lib/python3.7/multiprocessing/managers.py\", line 512, in connect\n    conn = Client(self._address, authkey=self._authkey)\n  File \"/usr/lib/python3.7/multiprocessing/connection.py\", line 492, in Client\n    c = SocketClient(address)\n  File \"/usr/lib/python3.7/multiprocessing/connection.py\", line 619, in SocketClient\n    s.connect(address)\nConnectionRefusedError: [Errno 111] Connection refused\n\nDuring handling of the above exception, another exception occurred:\n\nTraceback (most recent call last):\n  File \"./keepmenu\", line 1210, in \u003cmodule\u003e\n    run()\n  File \"./keepmenu\", line 1195, in run\n    dmenu = DmenuRunner(server)\n  File \"./keepmenu\", line 1046, in __init__\n    self.kpo = get_entries(self.database)\n  File \"./keepmenu\", line 317, in get_entries\n    kpo = PyKeePass(dbf, password, keyfile=keyfile)\n  File \"/usr/lib/python3.7/site-packages/pykeepass/pykeepass.py\", line 28, in __init__\n    self.read(password=password, keyfile=keyfile)\n  File \"/usr/lib/python3.7/site-packages/pykeepass/pykeepass.py\", line 45, in read\n    keyfile=keyfile\n  File \"/usr/lib/python3.7/site-packages/construct/core.py\", line 325, in parse_file\n    return self.parse_stream(f, **contextkw)\n  File \"/usr/lib/python3.7/site-packages/construct/core.py\", line 316, in parse_stream\n    return self._parsereport(stream, context, \"(parsing)\")\n  File \"/usr/lib/python3.7/site-packages/construct/core.py\", line 328, in _parsereport\n    obj = self._parse(stream, context, path)\n  File \"/usr/lib/python3.7/site-packages/construct/core.py\", line 1979, in _parse\n    subobj = sc._parsereport(stream, context, path)\n  File \"/usr/lib/python3.7/site-packages/construct/core.py\", line 328, in _parsereport\n    obj = self._parse(stream, context, path)\n  File \"/usr/lib/python3.7/site-packages/construct/core.py\", line 2468, in _parse\n    return self.subcon._parsereport(stream, context, path)\n  File \"/usr/lib/python3.7/site-packages/construct/core.py\", line 328, in _parsereport\n    obj = self._parse(stream, context, path)\n  File \"/usr/lib/python3.7/site-packages/construct/core.py\", line 3663, in _parse\n    return sc._parsereport(stream, context, path)\n  File \"/usr/lib/python3.7/site-packages/construct/core.py\", line 328, in _parsereport\n    obj = self._parse(stream, context, path)\n  File \"/usr/lib/python3.7/site-packages/construct/core.py\", line 1979, in _parse\n    subobj = sc._parsereport(stream, context, path)\n  File \"/usr/lib/python3.7/site-packages/construct/core.py\", line 328, in _parsereport\n    obj = self._parse(stream, context, path)\n  File \"/usr/lib/python3.7/site-packages/construct/core.py\", line 2468, in _parse\n    return self.subcon._parsereport(stream, context, path)\n  File \"/usr/lib/python3.7/site-packages/construct/core.py\", line 328, in _parsereport\n    obj = self._parse(stream, context, path)\n  File \"/usr/lib/python3.7/site-packages/construct/core.py\", line 2604, in _parse\n    return self.func(context) if callable(self.func) else self.func\n  File \"/usr/lib/python3.7/site-packages/pykeepass/kdbx_parsing/kdbx4.py\", line 55, in compute_transformed\n    key_composite\n  File \"/usr/lib/python3.7/site-packages/pykeepass/kdbx_parsing/common.py\", line 69, in aes_kdf\n    keyfile=keyfile\n  File \"/usr/lib/python3.7/site-packages/pykeepass/kdbx_parsing/common.py\", line 86, in compute_key_composite\n    password_composite = hashlib.sha256(password.encode('utf-8')).digest()\nAttributeError: 'bytes' object has no attribute 'encode'`","files":null},{"type":3,"author":{"id":"3c87de25ab8b2ec3449081ec888ea2a273bb79fc"},"timestamp":1549695730,"metadata":{"github-id":"MDEyOklzc3VlQ29tbWVudDQ2MjAyMDMyNg==","github-url":"https://github.com/firecat53/keepmenu/issues/27#issuecomment-462020326"},"message":"Try this: in the git version you downloaded, try changing line 285 to:\n\n    passw = res[0].decode(ENC).rstrip('\\n') if res[0] else passw\n\n(just add ENC in the decode() call). Run ./keepmenu from that directory to ensure you run the changed version.\n\nFWIW, I don't think this will work, but it's worth a try.\n\nIf it doesn't work, change your database password in keepassxc and try again with a brand new password. I know that sounds odd, but I'm having trouble figuring out where the error could be.","files":null},{"type":3,"author":{"id":"659e07177e84c4ab2c60eb2b276c03458373fbf7"},"timestamp":1549706331,"metadata":{"github-id":"MDEyOklzc3VlQ29tbWVudDQ2MjAzMDg0NQ==","github-url":"https://github.com/firecat53/keepmenu/issues/27#issuecomment-462030845"},"message":"No luck with either suggestion, unfortunately :(","files":null},{"type":3,"author":{"id":"3c87de25ab8b2ec3449081ec888ea2a273bb79fc"},"timestamp":1549740967,"metadata":{"github-id":"MDEyOklzc3VlQ29tbWVudDQ2MjA3Mjg2NQ==","github-url":"https://github.com/firecat53/keepmenu/issues/27#issuecomment-462072865"},"message":"Hrm. Create a new database in keepassxc and see if that one works. Maybe your database is an older Keepass version?","files":null},{"type":3,"author":{"id":"659e07177e84c4ab2c60eb2b276c03458373fbf7"},"timestamp":1549824084,"metadata":{"github-id":"MDEyOklzc3VlQ29tbWVudDQ2MjE1ODQ2OQ==","github-url":"https://github.com/firecat53/keepmenu/issues/27#issuecomment-462158469"},"message":"New DB works, so does the same one after an export/reimport to/from CSV.","files":null},{"type":6,"author":{"id":"659e07177e84c4ab2c60eb2b276c03458373fbf7"},"timestamp":1549824084,"metadata":{"github-id":"MDE1OlVzZXJDb250ZW50RWRpdDE4MjQxMTc5OQ=="},"target":"bb8ec08d288c7a441e730e35a269314496adca8cf7ccfe060d369aa502c47a2c","message":"New DB works, so does the same one after an export/reimport to/from CSV. \n\nEdit: must be a pykeepass bug, I have the same problem with passhole.","files":null},{"type":3,"author":{"id":"3c87de25ab8b2ec3449081ec888ea2a273bb79fc"},"timestamp":1549825460,"metadata":{"github-id":"MDEyOklzc3VlQ29tbWVudDQ2MjE2MTU1NQ==","github-url":"https://github.com/firecat53/keepmenu/issues/27#issuecomment-462161555"},"message":"Are you sure the database was a keepass 2.x version and not an older 1.x version database that maybe got renamed by mistake? Pykeepass only support kdbx3 and kdbx4 databases. In any case, sounds like we've resolved the issue for you?","files":null},{"type":3,"author":{"id":"659e07177e84c4ab2c60eb2b276c03458373fbf7"},"timestamp":1549832348,"metadata":{"github-id":"MDEyOklzc3VlQ29tbWVudDQ2MjE3MTU3OA==","github-url":"https://github.com/firecat53/keepmenu/issues/27#issuecomment-462171578"},"message":"Yes, it is a kdbx4 database - it actually used to work fine with keepmenu. Not sure what happened. Thanks for your help and sorry for the inconvenience.","files":null},{"type":6,"author":{"id":"659e07177e84c4ab2c60eb2b276c03458373fbf7"},"timestamp":1549832348,"metadata":{"github-id":"MDE1OlVzZXJDb250ZW50RWRpdDE4MjQyNzI1MQ=="},"target":"5d6868292079958d9e1b7b5b96a0d9414d525d229b890aec07262e4e38376712","message":"Yes, it is a kdbx4 database - it actually used to work fine with keepmenu. Not sure what happened. I suppose the issue can be closed. Thanks for your help and sorry for the inconvenience.","files":null},{"type":3,"author":{"id":"3c87de25ab8b2ec3449081ec888ea2a273bb79fc"},"timestamp":1549833278,"metadata":{"github-id":"MDEyOklzc3VlQ29tbWVudDQ2MjE3MzU4NA==","github-url":"https://github.com/firecat53/keepmenu/issues/27#issuecomment-462173584"},"message":"No worries, glad we figured it out!","files":null},{"type":4,"author":{"id":"3c87de25ab8b2ec3449081ec888ea2a273bb79fc"},"timestamp":1549833278,"metadata":{"github-id":"MDExOkNsb3NlZEV2ZW50MjEyOTQxODA4Mg=="},"status":2},{"type":3,"author":{"id":"183664e735945a0ae52171c1b163c02bc40a6074"},"timestamp":1577971168,"metadata":{"github-id":"MDEyOklzc3VlQ29tbWVudDU3MDIwNDk0Mw==","github-url":"https://github.com/firecat53/keepmenu/issues/27#issuecomment-570204943"},"message":"keepmenu\n  File \"/usr/local/bin/keepmenu\", line 444\n    nonlocal cmd\n               ^\nSyntaxError: invalid syntax\n\nThe question is what is missing","files":null},{"type":3,"author":{"id":"3c87de25ab8b2ec3449081ec888ea2a273bb79fc"},"timestamp":1577977489,"metadata":{"github-id":"MDEyOklzc3VlQ29tbWVudDU3MDIzNDAzNg==","github-url":"https://github.com/firecat53/keepmenu/issues/27#issuecomment-570234036"},"message":"@111lisu I'm sorry, I don't understand your comment. Can you please clarify?","files":null}]}