{"version":1,"ops":[{"type":1,"author":{"id":"4834f56d14f9a8cd6b243569767a65b9893bc972"},"timestamp":1521131311,"metadata":{"github-id":"MDU6SXNzdWUzMDU2MjYzNjg=","github-url":"https://github.com/firecat53/keepmenu/issues/4","origin":"github"},"title":"keepmenu crashing","message":"Am I missing a python  package?\nInstalled from aur\n\n```$ keepmenu \nTraceback (most recent call last):\n  File \"/usr/bin/keepmenu\", line 937, in \u003cmodule\u003e\n    MANAGER = client()\n  File \"/usr/bin/keepmenu\", line 755, in client\n    mgr.connect()\n  File \"/usr/lib/python3.6/multiprocessing/managers.py\", line 489, in connect\n    conn = Client(self._address, authkey=self._authkey)\n  File \"/usr/lib/python3.6/multiprocessing/connection.py\", line 487, in Client\n    c = SocketClient(address)\n  File \"/usr/lib/python3.6/multiprocessing/connection.py\", line 614, in SocketClient\n    s.connect(address)\nConnectionRefusedError: [Errno 111] Connection refused\n\nDuring handling of the above exception, another exception occurred:\n\nTraceback (most recent call last):\n  File \"/usr/bin/keepmenu\", line 941, in \u003cmodule\u003e\n    run()\n  File \"/usr/bin/keepmenu\", line 926, in run\n    dmenu = DmenuRunner(server)\n  File \"/usr/bin/keepmenu\", line 768, in __init__\n    self.database = get_database()\n  File \"/usr/bin/keepmenu\", line 280, in get_database\n    db_l[-1] = get_passphrase()\n  File \"/usr/bin/keepmenu\", line 344, in get_passphrase\n    password = dmenu_cmd(0, \"Passphrase\")\n  File \"/usr/bin/keepmenu\", line 220, in dmenu_cmd\n    extras = ([\"-\" + str(k), str(v)] for (k, v) in args_dict.items())\nUnboundLocalError: local variable 'args_dict' referenced before assignment```","files":null}]}