{"version":1,"ops":[{"type":1,"author":{"id":"7625833fc6c18ad167a5d534521a912dc64d8895"},"timestamp":1547069568,"metadata":{"github-id":"MDU6SXNzdWUzOTc1NzExMDg=","github-url":"https://github.com/firecat53/keepmenu/issues/17","origin":"github"},"title":"Unable to use password with %","message":"```\n ~/.config/keepmenu | keepmenu ed   \nTraceback (most recent call last):\n  File \"/home/varac/.local/bin/keepmenu\", line 1206, in \u003cmodule\u003e\n    MANAGER = client()\n  File \"/home/varac/.local/bin/keepmenu\", line 1032, in client\n    mgr.connect()\n  File \"/usr/lib/python3.6/multiprocessing/managers.py\", line 489, in connect\n    conn = Client(self._address, authkey=self._authkey)\n  File \"/usr/lib/python3.6/multiprocessing/connection.py\", line 487, in Client\n    c = SocketClient(address)\n  File \"/usr/lib/python3.6/multiprocessing/connection.py\", line 614, in SocketClient\n    s.connect(address)\nConnectionRefusedError: [Errno 111] Connection refused\n\nDuring handling of the above exception, another exception occurred:\n\nTraceback (most recent call last):\n  File \"/home/varac/.local/bin/keepmenu\", line 1210, in \u003cmodule\u003e\n    run()\n  File \"/home/varac/.local/bin/keepmenu\", line 1195, in run\n    dmenu = DmenuRunner(server)\n  File \"/home/varac/.local/bin/keepmenu\", line 1045, in __init__\n    self.database = get_database()\n  File \"/home/varac/.local/bin/keepmenu\", line 252, in get_database\n    args = CONF.items('database')\n  File \"/usr/lib/python3.6/configparser.py\", line 858, in items\n    return [(option, value_getter(option)) for option in d.keys()]\n  File \"/usr/lib/python3.6/configparser.py\", line 858, in \u003clistcomp\u003e\n    return [(option, value_getter(option)) for option in d.keys()]\n  File \"/usr/lib/python3.6/configparser.py\", line 855, in \u003clambda\u003e\n    section, option, d[option], d)\n  File \"/usr/lib/python3.6/configparser.py\", line 394, in before_get\n    self._interpolate_some(parser, option, L, value, section, defaults, 1)\n  File \"/usr/lib/python3.6/configparser.py\", line 444, in _interpolate_some\n    \"found: %r\" % (rest,))\nconfigparser.InterpolationSyntaxError: '%' must be followed by '%' or '(', found: '% ………'\n```\n\nEscaping the `%` with `%%` doesn't work neither, I get a `ChecksumError` then:\n\n```\nconstruct.core.ChecksumError: wrong checksum, read b'eccea587b10f3bb2e662a0f4c3e033a0dc85a73eafbac3cde82a42d455457f3d', computed b'0de2bf47f1955770e7c9663067938a7f88b21b74aa18365c768210da34452ddf'\n```\n\n(My password also contains brackets and spaces, not sure if this is related).\n\nAlso, one small documentation issue: Please document if it is possible/advised to use quotes for passwords which spaces, or if the quotes would be considered part of the password.","files":null}]}